<?xml version="1.0" encoding="UTF-8"?>
<testng-results skipped="0" failed="1" total="3" passed="2">
  <reporter-output>
  </reporter-output>
  <suite name="Suite" duration-ms="8019" started-at="2018-04-20T18:49:43Z" finished-at="2018-04-20T18:49:51Z">
    <groups>
    </groups>
    <test name="Test" duration-ms="8019" started-at="2018-04-20T18:49:43Z" finished-at="2018-04-20T18:49:51Z">
      <class name="teste.Testar">
        <test-method status="PASS" signature="setUp()[pri:0, instance:teste.Testar@66133adc]" name="setUp" is-config="true" duration-ms="4102" started-at="2018-04-20T15:49:43Z" finished-at="2018-04-20T15:49:47Z">
          <reporter-output>
          </reporter-output>
        </test-method> <!-- setUp -->
        <test-method status="PASS" signature="teste01()[pri:0, instance:teste.Testar@66133adc]" name="teste01" duration-ms="1413" started-at="2018-04-20T15:49:47Z" finished-at="2018-04-20T15:49:48Z">
          <reporter-output>
          </reporter-output>
        </test-method> <!-- teste01 -->
        <test-method status="PASS" signature="teste02()[pri:0, instance:teste.Testar@66133adc]" name="teste02" duration-ms="1290" started-at="2018-04-20T15:49:48Z" finished-at="2018-04-20T15:49:50Z">
          <reporter-output>
          </reporter-output>
        </test-method> <!-- teste02 -->
        <test-method status="FAIL" signature="teste03()[pri:0, instance:teste.Testar@66133adc]" name="teste03" duration-ms="1210" started-at="2018-04-20T15:49:50Z" finished-at="2018-04-20T15:49:51Z">
          <exception class="java.lang.AssertionError">
            <message>
              <![CDATA[expected [2] but found [1]]]>
            </message>
            <full-stacktrace>
              <![CDATA[java.lang.AssertionError: expected [2] but found [1]
	at org.testng.Assert.fail(Assert.java:94)
	at org.testng.Assert.failNotEquals(Assert.java:496)
	at org.testng.Assert.assertEquals(Assert.java:125)
	at org.testng.Assert.assertEquals(Assert.java:372)
	at org.testng.Assert.assertEquals(Assert.java:382)
	at teste.Testar.teste03(Testar.java:66)
	at sun.reflect.NativeMethodAccessorImpl.invoke0(Native Method)
	at sun.reflect.NativeMethodAccessorImpl.invoke(Unknown Source)
	at sun.reflect.DelegatingMethodAccessorImpl.invoke(Unknown Source)
	at java.lang.reflect.Method.invoke(Unknown Source)
	at org.testng.internal.MethodInvocationHelper.invokeMethod(MethodInvocationHelper.java:85)
	at org.testng.internal.Invoker.invokeMethod(Invoker.java:659)
	at org.testng.internal.Invoker.invokeTestMethod(Invoker.java:845)
	at org.testng.internal.Invoker.invokeTestMethods(Invoker.java:1153)
	at org.testng.internal.TestMethodWorker.invokeTestMethods(TestMethodWorker.java:125)
	at org.testng.internal.TestMethodWorker.run(TestMethodWorker.java:108)
	at org.testng.TestRunner.privateRun(TestRunner.java:771)
	at org.testng.TestRunner.run(TestRunner.java:621)
	at org.testng.SuiteRunner.runTest(SuiteRunner.java:357)
	at org.testng.SuiteRunner.runSequentially(SuiteRunner.java:352)
	at org.testng.SuiteRunner.privateRun(SuiteRunner.java:310)
	at org.testng.SuiteRunner.run(SuiteRunner.java:259)
	at org.testng.SuiteRunnerWorker.runSuite(SuiteRunnerWorker.java:52)
	at org.testng.SuiteRunnerWorker.run(SuiteRunnerWorker.java:86)
	at org.testng.TestNG.runSuitesSequentially(TestNG.java:1199)
	at org.testng.TestNG.runSuitesLocally(TestNG.java:1124)
	at org.testng.TestNG.run(TestNG.java:1032)
	at org.testng.TestNG.privateMain(TestNG.java:1339)
	at org.testng.TestNG.main(TestNG.java:1308)
]]>
            </full-stacktrace>
          </exception> <!-- java.lang.AssertionError -->
          <reporter-output>
          </reporter-output>
        </test-method> <!-- teste03 -->
      </class> <!-- teste.Testar -->
    </test> <!-- Test -->
  </suite> <!-- Suite -->
</testng-results>
